<?xml version="1.0"?>
<robot xmlns:xacro="http://www.ros.org/wiki/xacro" name="turtle">

    <!-- WIP NEED TO ENABLE PARAMETERS FOR THIS URDF -->
    <link name="world"></link>

    <!-- odom is the fixed starting position of the turtle robot -->
    <joint name="odom_joint" type="fixed">
        <origin xyz="3 3 0" rpy="0 0 0"/>
        <parent link="world"/>
        <child link="odom"/>        
    </joint>

    <link name="odom"></link>

    <!-- the turtle robot can move anywhere along the xy plane -->
    <!-- floating and planar joint types do not work so implement a cartesian workaround -->
    <joint name="x_joint" type="prismatic">
        <origin xyz="0 0 0" rpy="0 0 0"/>
        <parent link="odom"/>
        <child link="x_link"/> 
        <limit lower="-5" upper="5" velocity="100" effort="100"/>
        <axis xyz="1 0 0"/>
    </joint>

    <link name="x_link"></link>

    <joint name="y_joint" type="prismatic">
        <origin xyz="0 0 0" rpy="0 0 0"/>
        <parent link="x_link"/>
        <child link="y_link"/>
        <limit lower="-5" upper="5" velocity="100" effort="100"/>
        <axis xyz="0 1 0"/>
    </joint>

    <link name="y_link"></link>

    <!-- the turtle robot base_link -->
    <joint name="base_joint" type="fixed">
        <origin xyz="0 0 0" rpy="0 0 0"/>
        <parent link="y_link"/>
        <child link="base_link"/> 
    </joint>

    <link name="base_link">
        <visual>
            <origin xyz="0 0 0" rpy="0 0 0"/>
            <geometry>
                <box size="0.5 0.5 0.5" />
            </geometry>
            <material name="green">
                <color rgba="0.2 1 0.2 1"/>
            </material>
        </visual>
        <collision>
            <origin xyz="0 0 0" rpy="0 0 0"/>
            <geometry>
                <box size="0.5 0.5 0.5" />
            </geometry>
        </collision>
    </link>
<!-- 
    <joint name="cylindrical_joint" type="fixed">
        <origin xyz="0 0 0" rpy="0 0 0"/>
        <parent link="y_link"/>
        <child link="base_link"/> 
    </joint>

    <link name="cylindrical_link">
        <visual>
            <origin xyz="0 0 0" rpy="0 0 0"/>
            <geometry>
                <box size="0.5 0.5 0.5" />
            </geometry>
            <material name="green">
                <color rgba="0.2 1 0.2 1"/>
            </material>
        </visual>
        <collision>
            <origin xyz="0 0 0" rpy="0 0 0"/>
            <geometry>
                <box size="0.5 0.5 0.5" />
            </geometry>
        </collision>
    </link> -->


</robot>